<?xml version="1.0" encoding="UTF-8"?>
<robot generated="20181030 13:08:31.957" generator="Robot 3.0.4 (Python 2.7.15 on win32)">
<suite source="D:\svn\sources\SIWP9006\plc_system_test" id="s1" name="Plc System Test">
<suite source="D:\svn\sources\SIWP9006\plc_system_test\tc.3.3.3.robot" id="s1-s1" name="Tc.3.3.3">
<test id="s1-s1-t1" name="case 3.3.3.1">
<kw type="setup" name="Init Test">
<msg timestamp="20181030 13:08:32.020" level="FAIL">No keyword with name 'Init Test' found.</msg>
<status status="FAIL" endtime="20181030 13:08:32.020" starttime="20181030 13:08:32.020"></status>
</kw>
<kw type="teardown" name="Record Test Status">
<msg timestamp="20181030 13:08:32.023" level="FAIL">No keyword with name 'Record Test Status' found.</msg>
<status status="FAIL" endtime="20181030 13:08:32.023" starttime="20181030 13:08:32.023">No keyword with name 'Record Test Status' found.</status>
</kw>
<tags>
<tag>CCO</tag>
</tags>
<status status="FAIL" endtime="20181030 13:08:32.023" critical="yes" starttime="20181030 13:08:32.018">Setup failed:
No keyword with name 'Init Test' found.

Also teardown failed:
No keyword with name 'Record Test Status' found.</status>
</test>
<status status="FAIL" endtime="20181030 13:08:32.024" starttime="20181030 13:08:32.004"></status>
</suite>
<suite source="D:\svn\sources\SIWP9006\plc_system_test\tc.4.robot" id="s1-s2" name="Tc.4">
<test id="s1-s2-t1" name="tc_4.1">
<kw name="run iot test">
<arguments>
<arg>tc_4_1</arg>
</arguments>
<msg timestamp="20181030 13:08:32.030" level="FAIL">No keyword with name 'run iot test' found.</msg>
<status status="FAIL" endtime="20181030 13:08:32.030" starttime="20181030 13:08:32.030"></status>
</kw>
<kw type="teardown" name="Record Test Status">
<msg timestamp="20181030 13:08:32.033" level="FAIL">No keyword with name 'Record Test Status' found.</msg>
<status status="FAIL" endtime="20181030 13:08:32.033" starttime="20181030 13:08:32.032">No keyword with name 'Record Test Status' found.</status>
</kw>
<status status="FAIL" endtime="20181030 13:08:32.033" critical="yes" starttime="20181030 13:08:32.028">No keyword with name 'run iot test' found.

Also teardown failed:
No keyword with name 'Record Test Status' found.</status>
</test>
<status status="FAIL" endtime="20181030 13:08:32.033" starttime="20181030 13:08:32.024"></status>
</suite>
<status status="FAIL" endtime="20181030 13:08:32.034" starttime="20181030 13:08:31.987"></status>
</suite>
<statistics>
<total>
<stat fail="2" pass="0">Critical Tests</stat>
<stat fail="2" pass="0">All Tests</stat>
</total>
<tag>
<stat fail="1" pass="0">CCO</stat>
</tag>
<suite>
<stat fail="2" id="s1" name="Plc System Test" pass="0">Plc System Test</stat>
<stat fail="1" id="s1-s1" name="Tc.3.3.3" pass="0">Plc System Test.Tc.3.3.3</stat>
<stat fail="1" id="s1-s2" name="Tc.4" pass="0">Plc System Test.Tc.4</stat>
</suite>
</statistics>
<errors>
<msg timestamp="20181030 13:08:31.960" level="ERROR">Taking listener 'listener' into use failed: Importing listener 'listener' failed: ImportError: No module named serial
Traceback (most recent call last):
  File "D:\svn\sources\SIWP9006\plc_system_test\lib\listener.py", line 3, in &lt;module&gt;
    import plc_tb_ctrl
  File "D:\svn\sources\SIWP9006\plc_system_test\lib\plc_tb_ctrl.py", line 10, in &lt;module&gt;
    import serial
PYTHONPATH:
  D:\svn\sources\SIWP9006\plc_system_test\lib
  C:\windows\SYSTEM32\python27.zip
  C:\Program Files\python2\DLLs
  C:\Program Files\python2\lib
  C:\Program Files\python2\lib\plat-win
  C:\Program Files\python2\lib\lib-tk
  C:\Program Files\python2
  C:\Program Files\python2\lib\site-packages
  C:\Program Files\python2\lib\site-packages\wx-2.8-msw-unicode</msg>
<msg timestamp="20181030 13:08:32.016" level="ERROR">Error in file 'D:\svn\sources\SIWP9006\plc_system_test\tc.3.3.3.robot': Importing test library 'plc_tb_ctrl' failed: ImportError: No module named serial
Traceback (most recent call last):
  File "D:\svn\sources\SIWP9006\plc_system_test\lib\plc_tb_ctrl.py", line 10, in &lt;module&gt;
    import serial
PYTHONPATH:
  D:\svn\sources\SIWP9006\plc_system_test\lib
  C:\windows\SYSTEM32\python27.zip
  C:\Program Files\python2\DLLs
  C:\Program Files\python2\lib
  C:\Program Files\python2\lib\plat-win
  C:\Program Files\python2\lib\lib-tk
  C:\Program Files\python2
  C:\Program Files\python2\lib\site-packages
  C:\Program Files\python2\lib\site-packages\wx-2.8-msw-unicode</msg>
<msg timestamp="20181030 13:08:32.017" level="ERROR">Error in file 'D:\svn\sources\SIWP9006\plc_system_test\tc.3.3.3.robot': Importing test library 'plc_tb_ctrl.PlcSystemTestbench' failed: ImportError: No module named serial
Traceback (most recent call last):
  File "D:\svn\sources\SIWP9006\plc_system_test\lib\plc_tb_ctrl.py", line 10, in &lt;module&gt;
    import serial
PYTHONPATH:
  D:\svn\sources\SIWP9006\plc_system_test\lib
  C:\windows\SYSTEM32\python27.zip
  C:\Program Files\python2\DLLs
  C:\Program Files\python2\lib
  C:\Program Files\python2\lib\plat-win
  C:\Program Files\python2\lib\lib-tk
  C:\Program Files\python2
  C:\Program Files\python2\lib\site-packages
  C:\Program Files\python2\lib\site-packages\wx-2.8-msw-unicode</msg>
<msg timestamp="20181030 13:08:32.027" level="ERROR">Error in file 'D:\svn\sources\SIWP9006\plc_system_test\tc.4.robot': Importing test library 'D:\svn\sources\SIWP9006\plc_system_test\lib\plc_tb_ctrl.py' failed: ImportError: No module named serial
Traceback (most recent call last):
  File "D:\svn\sources\SIWP9006\plc_system_test\lib\plc_tb_ctrl.py", line 10, in &lt;module&gt;
    import serial
PYTHONPATH:
  D:\svn\sources\SIWP9006\plc_system_test\lib
  C:\windows\SYSTEM32\python27.zip
  C:\Program Files\python2\DLLs
  C:\Program Files\python2\lib
  C:\Program Files\python2\lib\plat-win
  C:\Program Files\python2\lib\lib-tk
  C:\Program Files\python2
  C:\Program Files\python2\lib\site-packages
  C:\Program Files\python2\lib\site-packages\wx-2.8-msw-unicode</msg>
<msg timestamp="20181030 13:08:32.027" level="ERROR">Error in file 'D:\svn\sources\SIWP9006\plc_system_test\tc.4.robot': Importing test library 'lib/plc_tb_ctrl.PlcSystemTestbench' failed: ImportError: Import by filename is not supported.
Traceback (most recent call last):
  None
PYTHONPATH:
  D:\svn\sources\SIWP9006\plc_system_test\lib
  C:\windows\SYSTEM32\python27.zip
  C:\Program Files\python2\DLLs
  C:\Program Files\python2\lib
  C:\Program Files\python2\lib\plat-win
  C:\Program Files\python2\lib\lib-tk
  C:\Program Files\python2
  C:\Program Files\python2\lib\site-packages
  C:\Program Files\python2\lib\site-packages\wx-2.8-msw-unicode</msg>
</errors>
</robot>
