<?xml version="1.0" encoding="UTF-8"?>
<robot generated="20181122 21:29:56.339" generator="Robot 3.0.2 (Python 2.7.15 on win32)">
<suite source="C:\D\plc_system_test" id="s1" name="Plc System Test">
<suite source="C:\D\plc_system_test\tc.3.2.1.robot" id="s1-s1" name="Tc.3.2.1">
<test id="s1-s1-t1" name="tc_3.2.1.1">
<kw type="setup" name="Init Test" library="plc_tb_ctrl">
<msg timestamp="20181122 21:29:56.676" level="INFO">start detail logging</msg>
<msg timestamp="20181122 21:29:56.677" level="INFO">start DUT logging</msg>
<msg timestamp="20181122 21:29:56.679" level="FAIL">WindowsError: [Error 2] </msg>
<msg timestamp="20181122 21:29:56.679" level="DEBUG">Traceback (most recent call last):
  File "C:\D\plc_system_test\lib\plc_tb_ctrl.py", line 187, in init_test
    TB_INSTANCE._start_dut_logging()
  File "C:\D\plc_system_test\lib\plc_tb_ctrl.py", line 1016, in _start_dut_logging
    "file={}".format(log_filename)])
  File "C:\Python27\lib\subprocess.py", line 394, in __init__
    errread, errwrite)
  File "C:\Python27\lib\subprocess.py", line 644, in _execute_child
    startupinfo)</msg>
<status status="FAIL" endtime="20181122 21:29:56.680" starttime="20181122 21:29:56.675"></status>
</kw>
<kw type="teardown" name="Record Test Status" library="plc_tb_ctrl">
<msg timestamp="20181122 21:29:56.681" level="INFO">begin 5 seconds waiting before exit...</msg>
<msg timestamp="20181122 21:30:01.681" level="INFO">stop DUT logging</msg>
<msg timestamp="20181122 21:30:01.682" level="FAIL">AttributeError: 'PlcSystemTestbench' object has no attribute 'dut_log'</msg>
<msg timestamp="20181122 21:30:01.683" level="DEBUG">Traceback (most recent call last):
  File "C:\D\plc_system_test\lib\plc_tb_ctrl.py", line 166, in record_test_status
    TB_INSTANCE._stop_dut_logging()
  File "C:\D\plc_system_test\lib\plc_tb_ctrl.py", line 1020, in _stop_dut_logging
    terminate_process(self.dut_log)</msg>
<status status="FAIL" endtime="20181122 21:30:01.683" starttime="20181122 21:29:56.680">AttributeError: 'PlcSystemTestbench' object has no attribute 'dut_log'</status>
</kw>
<tags>
<tag>CCO</tag>
</tags>
<status status="FAIL" endtime="20181122 21:30:01.684" critical="yes" starttime="20181122 21:29:56.674">Setup failed:
WindowsError: [Error 2] 

Also teardown failed:
AttributeError: 'PlcSystemTestbench' object has no attribute 'dut_log'</status>
</test>
<status status="FAIL" endtime="20181122 21:30:01.685" starttime="20181122 21:29:56.636"></status>
</suite>
<suite source="C:\D\plc_system_test\tc.4.robot" id="s1-s2" name="Tc.4">
<test id="s1-s2-t1" name="tc_4.1">
<kw name="run iot test">
<arguments>
<arg>tc_4_1</arg>
</arguments>
<msg timestamp="20181122 21:30:01.736" level="FAIL">No keyword with name 'run iot test' found.</msg>
<status status="FAIL" endtime="20181122 21:30:01.736" starttime="20181122 21:30:01.735"></status>
</kw>
<kw type="teardown" name="Record Test Status" library="plc_tb_ctrl">
<msg timestamp="20181122 21:30:01.737" level="FAIL">AttributeError: 'PlcSystemTestbench' object has no attribute 'detail_log_file'</msg>
<msg timestamp="20181122 21:30:01.738" level="DEBUG">Traceback (most recent call last):
  File "C:\D\plc_system_test\lib\plc_tb_ctrl.py", line 153, in record_test_status
    _trace_printf(tc_msg)
  File "C:\D\plc_system_test\lib\plc_tb_ctrl.py", line 88, in _trace_printf
    _write_log_file(LOG_ID_PRINTF, log_data)
  File "C:\D\plc_system_test\lib\plc_tb_ctrl.py", line 80, in _write_log_file
    if TB_INSTANCE.detail_log_file is not None:</msg>
<status status="FAIL" endtime="20181122 21:30:01.738" starttime="20181122 21:30:01.736">AttributeError: 'PlcSystemTestbench' object has no attribute 'detail_log_file'</status>
</kw>
<status status="FAIL" endtime="20181122 21:30:01.738" critical="yes" starttime="20181122 21:30:01.732">No keyword with name 'run iot test' found.

Also teardown failed:
AttributeError: 'PlcSystemTestbench' object has no attribute 'detail_log_file'</status>
</test>
<status status="FAIL" endtime="20181122 21:30:01.739" starttime="20181122 21:30:01.689"></status>
</suite>
<status status="FAIL" endtime="20181122 21:30:01.740" starttime="20181122 21:29:56.613"></status>
</suite>
<statistics>
<total>
<stat fail="2" pass="0">Critical Tests</stat>
<stat fail="2" pass="0">All Tests</stat>
</total>
<tag>
<stat fail="1" pass="0">CCO</stat>
</tag>
<suite>
<stat fail="2" id="s1" name="Plc System Test" pass="0">Plc System Test</stat>
<stat fail="1" id="s1-s1" name="Tc.3.2.1" pass="0">Plc System Test.Tc.3.2.1</stat>
<stat fail="1" id="s1-s2" name="Tc.4" pass="0">Plc System Test.Tc.4</stat>
</suite>
</statistics>
<errors>
<msg timestamp="20181122 21:29:56.673" level="ERROR">Error in file 'C:\D\plc_system_test\tc.3.2.1.robot': Initializing test library 'plc_tb_ctrl.PlcSystemTestbench' with no arguments failed: WindowsError: [Error 193] %1 \xb2\xbb\xca\xc7\xd3\xd0\xd0\xa7\xb5\xc4 Win32
Traceback (most recent call last):
  File "C:\D\plc_system_test\lib\plc_tb_ctrl.py", line 249, in __init__
    self.usb_relay_device = usb_relay.UsbRelay()
  File "C:\D\plc_system_test\lib\usb_relay.py", line 13, in __init__
    self.usb_relay_device = CDLL('usb_relay_device.dll')
  File "C:\Python27\lib\ctypes\__init__.py", line 366, in __init__
    self._handle = _dlopen(self._name, mode)</msg>
<msg timestamp="20181122 21:30:01.731" level="ERROR">Error in file 'C:\D\plc_system_test\tc.4.robot': Initializing test library 'plc_tb_ctrl.PlcSystemTestbench' with no arguments failed: WindowsError: [Error 183] : u'C:\\D\\plc_system_test\\log\\output-20181122-212956'
Traceback (most recent call last):
  File "C:\D\plc_system_test\lib\plc_tb_ctrl.py", line 246, in __init__
    self._create_log_file()
  File "C:\D\plc_system_test\lib\plc_tb_ctrl.py", line 994, in _create_log_file
    os.mkdir(output_dir)</msg>
</errors>
</robot>
